{
  "version": 8,
  "blockIdVersion": 10,
  "anchorX": 1,
  "anchorY": 8,
  "anchorZ": -2,
  "blocks": [
    {
      "x": -3,
      "y": 12,
      "z": -3,
      "name": "Plant_Leaves_Enchanted"
    },
    {
      "x": -3,
      "y": 13,
      "z": -3,
      "name": "Plant_Leaves_Enchanted"
    },
    {
      "x": -3,
      "y": 14,
      "z": -3,
      "name": "Plant_Leaves_Enchanted"
    },
    {
      "x": -3,
      "y": 11,
      "z": -2,
      "name": "Plant_Leaves_Enchanted"
    },
    {
      "x": -3,
      "y": 12,
      "z": -2,
      "name": "Plant_Leaves_Enchanted"
    },
    {
      "x": -3,
      "y": 13,
      "z": -2,
      "name": "Plant_Leaves_Enchanted"
    },
    {
      "x": -3,
      "y": 14,
      "z": -2,
      "name": "Plant_Fruit_Enchanted"
    },
    {
      "x": -3,
      "y": 12,
      "z": -1,
      "name": "Plant_Leaves_Enchanted"
    },
    {
      "x": -2,
      "y": 13,
      "z": -4,
      "name": "Plant_Leaves_Enchanted"
    },
    {
      "x": -2,
      "y": 14,
      "z": -4,
      "name": "Plant_Leaves_Enchanted"
    },
    {
      "x": -2,
      "y": 15,
      "z": -4,
      "name": "Plant_Leaves_Enchanted"
    },
    {
      "x": -2,
      "y": 16,
      "z": -4,
      "name": "Plant_Leaves_Enchanted"
    },
    {
      "x": -2,
      "y": 12,
      "z": -3,
      "name": "Plant_Leaves_Enchanted"
    },
    {
      "x": -2,
      "y": 13,
      "z": -3,
      "name": "Plant_Leaves_Enchanted"
    },
    {
      "x": -2,
      "y": 14,
      "z": -3,
      "name": "Plant_Leaves_Enchanted"
    },
    {
      "x": -2,
      "y": 15,
      "z": -3,
      "name": "Plant_Leaves_Enchanted"
    },
    {
      "x": -2,
      "y": 16,
      "z": -3,
      "name": "Plant_Fruit_Enchanted"
    },
    {
      "x": -2,
      "y": 11,
      "z": -2,
      "name": "Plant_Leaves_Enchanted"
    },
    {
      "x": -2,
      "y": 12,
      "z": -2,
      "name": "Plant_Leaves_Enchanted"
    },
    {
      "x": -2,
      "y": 13,
      "z": -2,
      "name": "Plant_Leaves_Enchanted"
    },
    {
      "x": -2,
      "y": 14,
      "z": -2,
      "name": "Plant_Leaves_Enchanted"
    },
    {
      "x": -2,
      "y": 11,
      "z": -1,
      "name": "Plant_Leaves_Enchanted"
    },
    {
      "x": -2,
      "y": 12,
      "z": -1,
      "name": "Plant_Leaves_Enchanted"
    },
    {
      "x": -2,
      "y": 13,
      "z": -1,
      "name": "Plant_Leaves_Enchanted"
    },
    {
      "x": -2,
      "y": 18,
      "z": -1,
      "name": "Plant_Leaves_Enchanted"
    },
    {
      "x": -2,
      "y": 19,
      "z": -1,
      "name": "Plant_Leaves_Enchanted"
    },
    {
      "x": -2,
      "y": 15,
      "z": 0,
      "name": "Plant_Leaves_Enchanted"
    },
    {
      "x": -2,
      "y": 16,
      "z": 0,
      "name": "Plant_Leaves_Enchanted"
    },
    {
      "x": -2,
      "y": 17,
      "z": 0,
      "name": "Plant_Leaves_Enchanted"
    },
    {
      "x": -2,
      "y": 18,
      "z": 0,
      "name": "Plant_Leaves_Enchanted"
    },
    {
      "x": -2,
      "y": 14,
      "z": 1,
      "name": "Plant_Leaves_Enchanted"
    },
    {
      "x": -2,
      "y": 15,
      "z": 1,
      "name": "Plant_Leaves_Enchanted"
    },
    {
      "x": -2,
      "y": 16,
      "z": 1,
      "name": "Plant_Leaves_Enchanted"
    },
    {
      "x": -2,
      "y": 15,
      "z": 2,
      "name": "Plant_Leaves_Enchanted"
    },
    {
      "x": -1,
      "y": 4,
      "z": -4,
      "name": "Wood_Azure_Roots"
    },
    {
      "x": -1,
      "y": 5,
      "z": -4,
      "name": "Wood_Enchanted_Trunk"
    },
    {
      "x": -1,
      "y": 6,
      "z": -4,
      "name": "Wood_Enchanted_Trunk"
    },
    {
      "x": -1,
      "y": 14,
      "z": -4,
      "name": "Plant_Leaves_Enchanted"
    },
    {
      "x": -1,
      "y": 15,
      "z": -4,
      "name": "Plant_Leaves_Enchanted"
    },
    {
      "x": -1,
      "y": 16,
      "z": -4,
      "name": "Plant_Leaves_Enchanted"
    },
    {
      "x": -1,
      "y": 17,
      "z": -4,
      "name": "Plant_Leaves_Enchanted"
    },
    {
      "x": -1,
      "y": 6,
      "z": -3,
      "name": "Wood_Enchanted_Trunk"
    },
    {
      "x": -1,
      "y": 7,
      "z": -3,
      "name": "Wood_Enchanted_Trunk"
    },
    {
      "x": -1,
      "y": 13,
      "z": -3,
      "name": "Plant_Leaves_Enchanted"
    },
    {
      "x": -1,
      "y": 14,
      "z": -3,
      "name": "Wood_Azure_Branch_Corner",
      "rotation": 2
    },
    {
      "x": -1,
      "y": 15,
      "z": -3,
      "name": "Wood_Azure_Branch_Long"
    },
    {
      "x": -1,
      "y": 16,
      "z": -3,
      "name": "Plant_Leaves_Enchanted"
    },
    {
      "x": -1,
      "y": 13,
      "z": -2,
      "name": "Wood_Azure_Branch_Corner",
      "rotation": 3
    },
    {
      "x": -1,
      "y": 14,
      "z": -2,
      "name": "Wood_Azure_Branch_Corner",
      "rotation": 10
    },
    {
      "x": -1,
      "y": 16,
      "z": -1,
      "name": "Plant_Leaves_Enchanted"
    },
    {
      "x": -1,
      "y": 17,
      "z": -1,
      "name": "Plant_Leaves_Enchanted"
    },
    {
      "x": -1,
      "y": 18,
      "z": -1,
      "name": "Plant_Leaves_Enchanted"
    },
    {
      "x": -1,
      "y": 15,
      "z": 0,
      "name": "Plant_Leaves_Enchanted"
    },
    {
      "x": -1,
      "y": 16,
      "z": 0,
      "name": "Plant_Leaves_Enchanted"
    },
    {
      "x": -1,
      "y": 17,
      "z": 0,
      "name": "Plant_Leaves_Enchanted"
    },
    {
      "x": -1,
      "y": 18,
      "z": 0,
      "name": "Plant_Fruit_Enchanted"
    },
    {
      "x": -1,
      "y": 13,
      "z": 1,
      "name": "Plant_Leaves_Enchanted"
    },
    {
      "x": -1,
      "y": 14,
      "z": 1,
      "name": "Plant_Leaves_Enchanted"
    },
    {
      "x": -1,
      "y": 15,
      "z": 1,
      "name": "Plant_Leaves_Enchanted"
    },
    {
      "x": -1,
      "y": 16,
      "z": 1,
      "name": "Plant_Leaves_Enchanted"
    },
    {
      "x": -1,
      "y": 17,
      "z": 1,
      "name": "Plant_Leaves_Enchanted"
    },
    {
      "x": -1,
      "y": 13,
      "z": 2,
      "name": "Plant_Leaves_Enchanted"
    },
    {
      "x": -1,
      "y": 14,
      "z": 2,
      "name": "Plant_Leaves_Enchanted"
    },
    {
      "x": -1,
      "y": 15,
      "z": 2,
      "name": "Plant_Leaves_Enchanted"
    },
    {
      "x": -1,
      "y": 16,
      "z": 2,
      "name": "Plant_Leaves_Enchanted"
    },
    {
      "x": 0,
      "y": 11,
      "z": -5,
      "name": "Plant_Leaves_Enchanted"
    },
    {
      "x": 0,
      "y": 12,
      "z": -5,
      "name": "Plant_Leaves_Enchanted"
    },
    {
      "x": 0,
      "y": 6,
      "z": -4,
      "name": "Wood_Enchanted_Trunk"
    },
    {
      "x": 0,
      "y": 7,
      "z": -4,
      "name": "Wood_Enchanted_Trunk"
    },
    {
      "x": 0,
      "y": 11,
      "z": -4,
      "name": "Plant_Leaves_Enchanted"
    },
    {
      "x": 0,
      "y": 12,
      "z": -4,
      "name": "Plant_Leaves_Enchanted"
    },
    {
      "x": 0,
      "y": 16,
      "z": -4,
      "name": "Plant_Leaves_Enchanted"
    },
    {
      "x": 0,
      "y": 17,
      "z": -4,
      "name": "Plant_Leaves_Enchanted"
    },
    {
      "x": 0,
      "y": 18,
      "z": -4,
      "name": "Plant_Leaves_Enchanted"
    },
    {
      "x": 0,
      "y": 5,
      "z": -3,
      "name": "Wood_Azure_Roots"
    },
    {
      "x": 0,
      "y": 6,
      "z": -3,
      "name": "Wood_Enchanted_Trunk"
    },
    {
      "x": 0,
      "y": 7,
      "z": -3,
      "name": "Wood_Enchanted_Trunk"
    },
    {
      "x": 0,
      "y": 8,
      "z": -3,
      "name": "Wood_Enchanted_Trunk"
    },
    {
      "x": 0,
      "y": 9,
      "z": -3,
      "name": "Wood_Enchanted_Trunk"
    },
    {
      "x": 0,
      "y": 17,
      "z": -3,
      "name": "Plant_Leaves_Enchanted"
    },
    {
      "x": 0,
      "y": 7,
      "z": -2,
      "name": "Wood_Enchanted_Trunk"
    },
    {
      "x": 0,
      "y": 8,
      "z": -2,
      "name": "Wood_Enchanted_Trunk"
    },
    {
      "x": 0,
      "y": 9,
      "z": -2,
      "name": "Wood_Enchanted_Trunk"
    },
    {
      "x": 0,
      "y": 10,
      "z": -2,
      "name": "Wood_Enchanted_Trunk"
    },
    {
      "x": 0,
      "y": 11,
      "z": -2,
      "name": "Wood_Enchanted_Trunk"
    },
    {
      "x": 0,
      "y": 13,
      "z": -2,
      "name": "Wood_Azure_Branch_Long",
      "rotation": 5
    },
    {
      "x": 0,
      "y": 14,
      "z": -2,
      "name": "Plant_Moss_Wall_Crystal",
      "rotation": 3
    },
    {
      "x": 0,
      "y": 21,
      "z": -2,
      "name": "Plant_Leaves_Enchanted"
    },
    {
      "x": 0,
      "y": 22,
      "z": -2,
      "name": "Plant_Leaves_Enchanted"
    },
    {
      "x": 0,
      "y": 23,
      "z": -2,
      "name": "Plant_Leaves_Enchanted"
    },
    {
      "x": 0,
      "y": 8,
      "z": -1,
      "name": "Wood_Enchanted_Trunk"
    },
    {
      "x": 0,
      "y": 9,
      "z": -1,
      "name": "Wood_Enchanted_Trunk"
    },
    {
      "x": 0,
      "y": 10,
      "z": -1,
      "name": "Plant_Moss_Wall_Crystal",
      "rotation": 3
    },
    {
      "x": 0,
      "y": 16,
      "z": -1,
      "name": "Wood_Azure_Branch_Long",
      "rotation": 5
    },
    {
      "x": 0,
      "y": 20,
      "z": -1,
      "name": "Plant_Leaves_Enchanted"
    },
    {
      "x": 0,
      "y": 21,
      "z": -1,
      "name": "Plant_Leaves_Enchanted"
    },
    {
      "x": 0,
      "y": 22,
      "z": -1,
      "name": "Plant_Leaves_Enchanted"
    },
    {
      "x": 0,
      "y": 23,
      "z": -1,
      "name": "Plant_Fruit_Enchanted"
    },
    {
      "x": 0,
      "y": 19,
      "z": 0,
      "name": "Plant_Leaves_Enchanted"
    },
    {
      "x": 0,
      "y": 20,
      "z": 0,
      "name": "Plant_Leaves_Enchanted"
    },
    {
      "x": 0,
      "y": 21,
      "z": 0,
      "name": "Plant_Leaves_Enchanted"
    },
    {
      "x": 0,
      "y": 13,
      "z": 1,
      "name": "Plant_Leaves_Enchanted"
    },
    {
      "x": 0,
      "y": 14,
      "z": 1,
      "name": "Plant_Leaves_Enchanted"
    },
    {
      "x": 0,
      "y": 15,
      "z": 1,
      "name": "Plant_Leaves_Enchanted"
    },
    {
      "x": 0,
      "y": 12,
      "z": 2,
      "name": "Plant_Leaves_Enchanted"
    },
    {
      "x": 0,
      "y": 13,
      "z": 2,
      "name": "Plant_Leaves_Enchanted"
    },
    {
      "x": 0,
      "y": 14,
      "z": 2,
      "name": "Plant_Leaves_Enchanted"
    },
    {
      "x": 0,
      "y": 15,
      "z": 2,
      "name": "Plant_Leaves_Enchanted"
    },
    {
      "x": 0,
      "y": 16,
      "z": 2,
      "name": "Plant_Leaves_Enchanted"
    },
    {
      "x": 0,
      "y": 13,
      "z": 3,
      "name": "Plant_Leaves_Enchanted"
    },
    {
      "x": 0,
      "y": 14,
      "z": 3,
      "name": "Plant_Leaves_Enchanted"
    },
    {
      "x": 1,
      "y": 13,
      "z": -6,
      "name": "Plant_Leaves_Enchanted"
    },
    {
      "x": 1,
      "y": 14,
      "z": -6,
      "name": "Plant_Fruit_Enchanted"
    },
    {
      "x": 1,
      "y": 11,
      "z": -5,
      "name": "Plant_Leaves_Enchanted"
    },
    {
      "x": 1,
      "y": 12,
      "z": -5,
      "name": "Plant_Leaves_Enchanted"
    },
    {
      "x": 1,
      "y": 13,
      "z": -5,
      "name": "Plant_Leaves_Enchanted"
    },
    {
      "x": 1,
      "y": 14,
      "z": -5,
      "name": "Plant_Leaves_Enchanted"
    },
    {
      "x": 1,
      "y": 11,
      "z": -4,
      "name": "Plant_Leaves_Enchanted"
    },
    {
      "x": 1,
      "y": 13,
      "z": -4,
      "name": "Wood_Azure_Branch_Long",
      "rotation": 4
    },
    {
      "x": 1,
      "y": 7,
      "z": -3,
      "name": "Wood_Enchanted_Trunk"
    },
    {
      "x": 1,
      "y": 8,
      "z": -3,
      "name": "Wood_Enchanted_Trunk"
    },
    {
      "x": 1,
      "y": 13,
      "z": -3,
      "name": "Wood_Azure_Branch_Long",
      "rotation": 4
    },
    {
      "x": 1,
      "y": 14,
      "z": -3,
      "name": "Plant_Moss_Wall_Crystal",
      "rotation": 2
    },
    {
      "x": 1,
      "y": 7,
      "z": -2,
      "name": "Wood_Enchanted_Trunk"
    },
    {
      "x": 1,
      "y": 8,
      "z": -2,
      "name": "Wood_Enchanted_Trunk"
    },
    {
      "x": 1,
      "y": 9,
      "z": -2,
      "name": "Wood_Enchanted_Trunk"
    },
    {
      "x": 1,
      "y": 10,
      "z": -2,
      "name": "Wood_Enchanted_Trunk"
    },
    {
      "x": 1,
      "y": 11,
      "z": -2,
      "name": "Wood_Enchanted_Trunk"
    },
    {
      "x": 1,
      "y": 12,
      "z": -2,
      "name": "Wood_Enchanted_Trunk"
    },
    {
      "x": 1,
      "y": 13,
      "z": -2,
      "name": "Wood_Enchanted_Trunk"
    },
    {
      "x": 1,
      "y": 14,
      "z": -2,
      "name": "Wood_Enchanted_Trunk"
    },
    {
      "x": 1,
      "y": 15,
      "z": -2,
      "name": "Plant_Moss_Rug_Crystal"
    },
    {
      "x": 1,
      "y": 7,
      "z": -1,
      "name": "Wood_Enchanted_Trunk"
    },
    {
      "x": 1,
      "y": 8,
      "z": -1,
      "name": "Wood_Enchanted_Trunk"
    },
    {
      "x": 1,
      "y": 9,
      "z": -1,
      "name": "Wood_Enchanted_Trunk"
    },
    {
      "x": 1,
      "y": 10,
      "z": -1,
      "name": "Wood_Enchanted_Trunk"
    },
    {
      "x": 1,
      "y": 11,
      "z": -1,
      "name": "Wood_Enchanted_Trunk"
    },
    {
      "x": 1,
      "y": 12,
      "z": -1,
      "name": "Wood_Enchanted_Trunk"
    },
    {
      "x": 1,
      "y": 13,
      "z": -1,
      "name": "Wood_Enchanted_Trunk"
    },
    {
      "x": 1,
      "y": 14,
      "z": -1,
      "name": "Wood_Enchanted_Trunk"
    },
    {
      "x": 1,
      "y": 15,
      "z": -1,
      "name": "Wood_Enchanted_Trunk"
    },
    {
      "x": 1,
      "y": 16,
      "z": -1,
      "name": "Wood_Enchanted_Trunk"
    },
    {
      "x": 1,
      "y": 17,
      "z": -1,
      "name": "Wood_Azure_Branch_Long"
    },
    {
      "x": 1,
      "y": 18,
      "z": -1,
      "name": "Wood_Azure_Branch_Long"
    },
    {
      "x": 1,
      "y": 19,
      "z": -1,
      "name": "Plant_Leaves_Enchanted"
    },
    {
      "x": 1,
      "y": 20,
      "z": -1,
      "name": "Plant_Leaves_Enchanted"
    },
    {
      "x": 1,
      "y": 21,
      "z": -1,
      "name": "Plant_Leaves_Enchanted"
    },
    {
      "x": 1,
      "y": 5,
      "z": 0,
      "name": "Wood_Azure_Roots"
    },
    {
      "x": 1,
      "y": 6,
      "z": 0,
      "name": "Wood_Enchanted_Trunk"
    },
    {
      "x": 1,
      "y": 7,
      "z": 0,
      "name": "Wood_Enchanted_Trunk"
    },
    {
      "x": 1,
      "y": 8,
      "z": 0,
      "name": "Wood_Enchanted_Trunk"
    },
    {
      "x": 1,
      "y": 10,
      "z": 0,
      "name": "Plant_Moss_Wall_Crystal"
    },
    {
      "x": 1,
      "y": 13,
      "z": 0,
      "name": "Wood_Azure_Branch_Long",
      "rotation": 4
    },
    {
      "x": 1,
      "y": 18,
      "z": 0,
      "name": "Plant_Leaves_Enchanted"
    },
    {
      "x": 1,
      "y": 19,
      "z": 0,
      "name": "Plant_Leaves_Enchanted"
    },
    {
      "x": 1,
      "y": 20,
      "z": 0,
      "name": "Plant_Leaves_Enchanted"
    },
    {
      "x": 1,
      "y": 21,
      "z": 0,
      "name": "Plant_Leaves_Enchanted"
    },
    {
      "x": 1,
      "y": 6,
      "z": 1,
      "name": "Wood_Enchanted_Trunk"
    },
    {
      "x": 1,
      "y": 7,
      "z": 1,
      "name": "Wood_Enchanted_Trunk"
    },
    {
      "x": 1,
      "y": 12,
      "z": 1,
      "name": "Plant_Leaves_Enchanted"
    },
    {
      "x": 1,
      "y": 13,
      "z": 1,
      "name": "Plant_Leaves_Enchanted"
    },
    {
      "x": 1,
      "y": 14,
      "z": 1,
      "name": "Plant_Leaves_Enchanted"
    },
    {
      "x": 1,
      "y": 19,
      "z": 1,
      "name": "Plant_Leaves_Enchanted"
    },
    {
      "x": 1,
      "y": 20,
      "z": 1,
      "name": "Plant_Leaves_Enchanted"
    },
    {
      "x": 1,
      "y": 11,
      "z": 2,
      "name": "Plant_Leaves_Enchanted"
    },
    {
      "x": 1,
      "y": 12,
      "z": 2,
      "name": "Plant_Leaves_Enchanted"
    },
    {
      "x": 1,
      "y": 15,
      "z": 2,
      "name": "Plant_Leaves_Enchanted"
    },
    {
      "x": 1,
      "y": 16,
      "z": 2,
      "name": "Plant_Fruit_Enchanted"
    },
    {
      "x": 1,
      "y": 12,
      "z": 3,
      "name": "Plant_Leaves_Enchanted"
    },
    {
      "x": 1,
      "y": 13,
      "z": 3,
      "name": "Plant_Leaves_Enchanted"
    },
    {
      "x": 1,
      "y": 14,
      "z": 3,
      "name": "Plant_Leaves_Enchanted"
    },
    {
      "x": 2,
      "y": 12,
      "z": -6,
      "name": "Plant_Leaves_Enchanted"
    },
    {
      "x": 2,
      "y": 13,
      "z": -6,
      "name": "Plant_Leaves_Enchanted"
    },
    {
      "x": 2,
      "y": 14,
      "z": -6,
      "name": "Plant_Leaves_Enchanted"
    },
    {
      "x": 2,
      "y": 12,
      "z": -5,
      "name": "Plant_Leaves_Enchanted"
    },
    {
      "x": 2,
      "y": 13,
      "z": -5,
      "name": "Plant_Leaves_Enchanted"
    },
    {
      "x": 2,
      "y": 14,
      "z": -5,
      "name": "Plant_Leaves_Enchanted"
    },
    {
      "x": 2,
      "y": 14,
      "z": -4,
      "name": "Plant_Leaves_Enchanted"
    },
    {
      "x": 2,
      "y": 15,
      "z": -4,
      "name": "Plant_Leaves_Enchanted"
    },
    {
      "x": 2,
      "y": 14,
      "z": -2,
      "name": "Plant_Moss_Wall_Crystal",
      "rotation": 1
    },
    {
      "x": 2,
      "y": 7,
      "z": -1,
      "name": "Wood_Enchanted_Trunk"
    },
    {
      "x": 2,
      "y": 8,
      "z": -1,
      "name": "Wood_Enchanted_Trunk"
    },
    {
      "x": 2,
      "y": 15,
      "z": -1,
      "name": "Wood_Azure_Branch_Long",
      "rotation": 5
    },
    {
      "x": 2,
      "y": 6,
      "z": 0,
      "name": "Wood_Enchanted_Trunk"
    },
    {
      "x": 2,
      "y": 7,
      "z": 0,
      "name": "Wood_Enchanted_Trunk"
    },
    {
      "x": 2,
      "y": 12,
      "z": 0,
      "name": "Plant_Leaves_Enchanted"
    },
    {
      "x": 2,
      "y": 13,
      "z": 0,
      "name": "Plant_Leaves_Enchanted"
    },
    {
      "x": 2,
      "y": 17,
      "z": 0,
      "name": "Plant_Leaves_Enchanted"
    },
    {
      "x": 2,
      "y": 18,
      "z": 0,
      "name": "Plant_Leaves_Enchanted"
    },
    {
      "x": 2,
      "y": 19,
      "z": 0,
      "name": "Plant_Leaves_Enchanted"
    },
    {
      "x": 2,
      "y": 20,
      "z": 0,
      "name": "Plant_Leaves_Enchanted"
    },
    {
      "x": 2,
      "y": 21,
      "z": 0,
      "name": "Plant_Fruit_Enchanted"
    },
    {
      "x": 2,
      "y": 4,
      "z": 1,
      "name": "Wood_Azure_Roots"
    },
    {
      "x": 2,
      "y": 5,
      "z": 1,
      "name": "Wood_Enchanted_Trunk"
    },
    {
      "x": 2,
      "y": 6,
      "z": 1,
      "name": "Wood_Enchanted_Trunk"
    },
    {
      "x": 2,
      "y": 10,
      "z": 1,
      "name": "Plant_Leaves_Enchanted"
    },
    {
      "x": 2,
      "y": 11,
      "z": 1,
      "name": "Plant_Leaves_Enchanted"
    },
    {
      "x": 2,
      "y": 12,
      "z": 1,
      "name": "Plant_Leaves_Enchanted"
    },
    {
      "x": 2,
      "y": 14,
      "z": 1,
      "name": "Plant_Leaves_Enchanted"
    },
    {
      "x": 2,
      "y": 18,
      "z": 1,
      "name": "Plant_Leaves_Enchanted"
    },
    {
      "x": 2,
      "y": 19,
      "z": 1,
      "name": "Plant_Leaves_Enchanted"
    },
    {
      "x": 2,
      "y": 11,
      "z": 2,
      "name": "Plant_Leaves_Enchanted"
    },
    {
      "x": 2,
      "y": 12,
      "z": 2,
      "name": "Plant_Leaves_Enchanted"
    },
    {
      "x": 2,
      "y": 13,
      "z": 2,
      "name": "Plant_Leaves_Enchanted"
    },
    {
      "x": 2,
      "y": 14,
      "z": 2,
      "name": "Plant_Leaves_Enchanted"
    },
    {
      "x": 2,
      "y": 12,
      "z": 3,
      "name": "Plant_Leaves_Enchanted"
    },
    {
      "x": 2,
      "y": 13,
      "z": 3,
      "name": "Plant_Leaves_Enchanted"
    },
    {
      "x": 3,
      "y": 13,
      "z": -6,
      "name": "Plant_Leaves_Enchanted"
    },
    {
      "x": 3,
      "y": 12,
      "z": -5,
      "name": "Plant_Leaves_Enchanted"
    },
    {
      "x": 3,
      "y": 13,
      "z": -5,
      "name": "Plant_Leaves_Enchanted"
    },
    {
      "x": 3,
      "y": 14,
      "z": -5,
      "name": "Plant_Leaves_Enchanted"
    },
    {
      "x": 3,
      "y": 15,
      "z": -5,
      "name": "Plant_Leaves_Enchanted"
    },
    {
      "x": 3,
      "y": 16,
      "z": -5,
      "name": "Plant_Fruit_Enchanted"
    },
    {
      "x": 3,
      "y": 12,
      "z": -4,
      "name": "Plant_Leaves_Enchanted"
    },
    {
      "x": 3,
      "y": 13,
      "z": -4,
      "name": "Plant_Leaves_Enchanted"
    },
    {
      "x": 3,
      "y": 14,
      "z": -4,
      "name": "Plant_Leaves_Enchanted"
    },
    {
      "x": 3,
      "y": 15,
      "z": -4,
      "name": "Plant_Leaves_Enchanted"
    },
    {
      "x": 3,
      "y": 15,
      "z": -3,
      "name": "Plant_Leaves_Enchanted"
    },
    {
      "x": 3,
      "y": 16,
      "z": -3,
      "name": "Plant_Leaves_Enchanted"
    },
    {
      "x": 3,
      "y": 16,
      "z": -2,
      "name": "Plant_Leaves_Enchanted"
    },
    {
      "x": 3,
      "y": 17,
      "z": -2,
      "name": "Plant_Leaves_Enchanted"
    },
    {
      "x": 3,
      "y": 10,
      "z": -1,
      "name": "Plant_Leaves_Enchanted"
    },
    {
      "x": 3,
      "y": 11,
      "z": -1,
      "name": "Plant_Leaves_Enchanted"
    },
    {
      "x": 3,
      "y": 12,
      "z": -1,
      "name": "Plant_Leaves_Enchanted"
    },
    {
      "x": 3,
      "y": 15,
      "z": -1,
      "name": "Wood_Azure_Branch_Long",
      "rotation": 5
    },
    {
      "x": 3,
      "y": 17,
      "z": -1,
      "name": "Plant_Leaves_Enchanted"
    },
    {
      "x": 3,
      "y": 18,
      "z": -1,
      "name": "Plant_Leaves_Enchanted"
    },
    {
      "x": 3,
      "y": 19,
      "z": -1,
      "name": "Plant_Leaves_Enchanted"
    },
    {
      "x": 3,
      "y": 10,
      "z": 0,
      "name": "Plant_Leaves_Enchanted"
    },
    {
      "x": 3,
      "y": 11,
      "z": 0,
      "name": "Plant_Leaves_Enchanted"
    },
    {
      "x": 3,
      "y": 12,
      "z": 0,
      "name": "Plant_Leaves_Enchanted"
    },
    {
      "x": 3,
      "y": 13,
      "z": 0,
      "name": "Plant_Leaves_Enchanted"
    },
    {
      "x": 3,
      "y": 16,
      "z": 0,
      "name": "Plant_Leaves_Enchanted"
    },
    {
      "x": 3,
      "y": 17,
      "z": 0,
      "name": "Plant_Leaves_Enchanted"
    },
    {
      "x": 3,
      "y": 18,
      "z": 0,
      "name": "Plant_Leaves_Enchanted"
    },
    {
      "x": 3,
      "y": 19,
      "z": 0,
      "name": "Plant_Leaves_Enchanted"
    },
    {
      "x": 3,
      "y": 10,
      "z": 1,
      "name": "Plant_Leaves_Enchanted"
    },
    {
      "x": 3,
      "y": 11,
      "z": 1,
      "name": "Plant_Leaves_Enchanted"
    },
    {
      "x": 3,
      "y": 12,
      "z": 1,
      "name": "Plant_Leaves_Enchanted"
    },
    {
      "x": 3,
      "y": 13,
      "z": 1,
      "name": "Plant_Leaves_Enchanted"
    },
    {
      "x": 3,
      "y": 14,
      "z": 1,
      "name": "Plant_Fruit_Enchanted"
    },
    {
      "x": 3,
      "y": 17,
      "z": 1,
      "name": "Plant_Leaves_Enchanted"
    },
    {
      "x": 3,
      "y": 18,
      "z": 1,
      "name": "Plant_Leaves_Enchanted"
    },
    {
      "x": 3,
      "y": 11,
      "z": 2,
      "name": "Plant_Leaves_Enchanted"
    },
    {
      "x": 3,
      "y": 12,
      "z": 2,
      "name": "Plant_Leaves_Enchanted"
    },
    {
      "x": 4,
      "y": 13,
      "z": -5,
      "name": "Plant_Leaves_Enchanted"
    },
    {
      "x": 4,
      "y": 14,
      "z": -5,
      "name": "Plant_Leaves_Enchanted"
    },
    {
      "x": 4,
      "y": 13,
      "z": -4,
      "name": "Plant_Leaves_Enchanted"
    },
    {
      "x": 4,
      "y": 14,
      "z": -4,
      "name": "Plant_Leaves_Enchanted"
    },
    {
      "x": 4,
      "y": 15,
      "z": -4,
      "name": "Plant_Leaves_Enchanted"
    },
    {
      "x": 4,
      "y": 16,
      "z": -4,
      "name": "Plant_Leaves_Enchanted"
    },
    {
      "x": 4,
      "y": 13,
      "z": -3,
      "name": "Plant_Leaves_Enchanted"
    },
    {
      "x": 4,
      "y": 14,
      "z": -3,
      "name": "Plant_Leaves_Enchanted"
    },
    {
      "x": 4,
      "y": 15,
      "z": -3,
      "name": "Plant_Leaves_Enchanted"
    },
    {
      "x": 4,
      "y": 16,
      "z": -3,
      "name": "Plant_Leaves_Enchanted"
    },
    {
      "x": 4,
      "y": 17,
      "z": -3,
      "name": "Plant_Leaves_Enchanted"
    },
    {
      "x": 4,
      "y": 18,
      "z": -3,
      "name": "Plant_Fruit_Enchanted"
    },
    {
      "x": 4,
      "y": 14,
      "z": -2,
      "name": "Plant_Leaves_Enchanted"
    },
    {
      "x": 4,
      "y": 15,
      "z": -2,
      "name": "Plant_Leaves_Enchanted"
    },
    {
      "x": 4,
      "y": 16,
      "z": -2,
      "name": "Plant_Leaves_Enchanted"
    },
    {
      "x": 4,
      "y": 17,
      "z": -2,
      "name": "Plant_Leaves_Enchanted"
    },
    {
      "x": 4,
      "y": 18,
      "z": -2,
      "name": "Plant_Leaves_Enchanted"
    },
    {
      "x": 4,
      "y": 10,
      "z": -1,
      "name": "Plant_Leaves_Enchanted"
    },
    {
      "x": 4,
      "y": 11,
      "z": -1,
      "name": "Plant_Leaves_Enchanted"
    },
    {
      "x": 4,
      "y": 15,
      "z": -1,
      "name": "Plant_Leaves_Enchanted"
    },
    {
      "x": 4,
      "y": 16,
      "z": -1,
      "name": "Plant_Leaves_Enchanted"
    },
    {
      "x": 4,
      "y": 17,
      "z": -1,
      "name": "Plant_Leaves_Enchanted"
    },
    {
      "x": 4,
      "y": 18,
      "z": -1,
      "name": "Plant_Leaves_Enchanted"
    },
    {
      "x": 4,
      "y": 19,
      "z": -1,
      "name": "Plant_Fruit_Enchanted"
    },
    {
      "x": 4,
      "y": 10,
      "z": 0,
      "name": "Plant_Leaves_Enchanted"
    },
    {
      "x": 4,
      "y": 11,
      "z": 0,
      "name": "Plant_Leaves_Enchanted"
    },
    {
      "x": 4,
      "y": 12,
      "z": 0,
      "name": "Plant_Leaves_Enchanted"
    },
    {
      "x": 4,
      "y": 16,
      "z": 0,
      "name": "Plant_Leaves_Enchanted"
    },
    {
      "x": 4,
      "y": 17,
      "z": 0,
      "name": "Plant_Leaves_Enchanted"
    },
    {
      "x": 4,
      "y": 11,
      "z": 1,
      "name": "Plant_Leaves_Enchanted"
    },
    {
      "x": 5,
      "y": 14,
      "z": -4,
      "name": "Plant_Leaves_Enchanted"
    },
    {
      "x": 5,
      "y": 15,
      "z": -4,
      "name": "Plant_Leaves_Enchanted"
    },
    {
      "x": 5,
      "y": 14,
      "z": -3,
      "name": "Plant_Leaves_Enchanted"
    },
    {
      "x": 5,
      "y": 15,
      "z": -3,
      "name": "Plant_Leaves_Enchanted"
    },
    {
      "x": 5,
      "y": 16,
      "z": -3,
      "name": "Plant_Leaves_Enchanted"
    },
    {
      "x": 5,
      "y": 15,
      "z": -2,
      "name": "Plant_Leaves_Enchanted"
    },
    {
      "x": 5,
      "y": 16,
      "z": -2,
      "name": "Plant_Leaves_Enchanted"
    },
    {
      "x": 5,
      "y": 17,
      "z": -2,
      "name": "Plant_Leaves_Enchanted"
    },
    {
      "x": 5,
      "y": 16,
      "z": -1,
      "name": "Plant_Leaves_Enchanted"
    },
    {
      "x": 5,
      "y": 17,
      "z": -1,
      "name": "Plant_Leaves_Enchanted"
    }
  ]
}