{
  "version": 8,
  "blockIdVersion": 10,
  "anchorX": 2,
  "anchorY": 4,
  "anchorZ": -2,
  "blocks": [
    {
      "x": -1,
      "y": 8,
      "z": -2,
      "name": "Plant_Leaves_Enchanted"
    },
    {
      "x": -1,
      "y": 9,
      "z": -2,
      "name": "Plant_Leaves_Enchanted"
    },
    {
      "x": -1,
      "y": 10,
      "z": -2,
      "name": "Plant_Fruit_Enchanted"
    },
    {
      "x": -1,
      "y": 8,
      "z": -1,
      "name": "Plant_Leaves_Enchanted"
    },
    {
      "x": -1,
      "y": 9,
      "z": -1,
      "name": "Plant_Leaves_Enchanted"
    },
    {
      "x": -1,
      "y": 10,
      "z": -1,
      "name": "Plant_Leaves_Enchanted"
    },
    {
      "x": -1,
      "y": 8,
      "z": 0,
      "name": "Plant_Leaves_Enchanted"
    },
    {
      "x": -1,
      "y": 9,
      "z": 0,
      "name": "Plant_Leaves_Enchanted"
    },
    {
      "x": 0,
      "y": 8,
      "z": -3,
      "name": "Plant_Leaves_Enchanted"
    },
    {
      "x": 0,
      "y": 9,
      "z": -3,
      "name": "Plant_Leaves_Enchanted"
    },
    {
      "x": 0,
      "y": 7,
      "z": -2,
      "name": "Plant_Leaves_Enchanted"
    },
    {
      "x": 0,
      "y": 8,
      "z": -2,
      "name": "Plant_Leaves_Enchanted"
    },
    {
      "x": 0,
      "y": 9,
      "z": -2,
      "name": "Plant_Leaves_Enchanted"
    },
    {
      "x": 0,
      "y": 10,
      "z": -2,
      "name": "Plant_Leaves_Enchanted",
      "rotation": 2
    },
    {
      "x": 0,
      "y": 7,
      "z": -1,
      "name": "Plant_Leaves_Enchanted"
    },
    {
      "x": 0,
      "y": 8,
      "z": -1,
      "name": "Plant_Leaves_Enchanted"
    },
    {
      "x": 0,
      "y": 9,
      "z": -1,
      "name": "Plant_Leaves_Enchanted"
    },
    {
      "x": 0,
      "y": 10,
      "z": -1,
      "name": "Plant_Leaves_Enchanted"
    },
    {
      "x": 0,
      "y": 11,
      "z": -1,
      "name": "Plant_Leaves_Enchanted"
    },
    {
      "x": 0,
      "y": 8,
      "z": 0,
      "name": "Plant_Leaves_Enchanted"
    },
    {
      "x": 0,
      "y": 9,
      "z": 0,
      "name": "Plant_Leaves_Enchanted"
    },
    {
      "x": 0,
      "y": 10,
      "z": 0,
      "name": "Plant_Leaves_Enchanted"
    },
    {
      "x": 0,
      "y": 11,
      "z": 0,
      "name": "Plant_Leaves_Enchanted"
    },
    {
      "x": 0,
      "y": 9,
      "z": 1,
      "name": "Plant_Leaves_Enchanted"
    },
    {
      "x": 0,
      "y": 10,
      "z": 1,
      "name": "Plant_Leaves_Enchanted"
    },
    {
      "x": 1,
      "y": 8,
      "z": -2,
      "name": "Wood_Azure_Branch_Long",
      "rotation": 5
    },
    {
      "x": 1,
      "y": 10,
      "z": -2,
      "name": "Wood_Azure_Branch_Long",
      "rotation": 5
    },
    {
      "x": 1,
      "y": 8,
      "z": -1,
      "name": "Plant_Leaves_Enchanted"
    },
    {
      "x": 1,
      "y": 9,
      "z": -1,
      "name": "Plant_Leaves_Enchanted"
    },
    {
      "x": 1,
      "y": 10,
      "z": -1,
      "name": "Plant_Leaves_Enchanted"
    },
    {
      "x": 1,
      "y": 8,
      "z": 0,
      "name": "Plant_Leaves_Enchanted"
    },
    {
      "x": 1,
      "y": 9,
      "z": 0,
      "name": "Plant_Leaves_Enchanted"
    },
    {
      "x": 1,
      "y": 10,
      "z": 0,
      "name": "Plant_Leaves_Enchanted"
    },
    {
      "x": 1,
      "y": 11,
      "z": 0,
      "name": "Plant_Leaves_Enchanted"
    },
    {
      "x": 1,
      "y": 12,
      "z": 0,
      "name": "Plant_Leaves_Enchanted"
    },
    {
      "x": 1,
      "y": 13,
      "z": 0,
      "name": "Plant_Fruit_Enchanted"
    },
    {
      "x": 1,
      "y": 8,
      "z": 1,
      "name": "Plant_Leaves_Enchanted"
    },
    {
      "x": 1,
      "y": 9,
      "z": 1,
      "name": "Plant_Leaves_Enchanted"
    },
    {
      "x": 1,
      "y": 10,
      "z": 1,
      "name": "Plant_Leaves_Enchanted"
    },
    {
      "x": 1,
      "y": 11,
      "z": 1,
      "name": "Plant_Leaves_Enchanted"
    },
    {
      "x": 2,
      "y": 9,
      "z": -4,
      "name": "Plant_Leaves_Enchanted"
    },
    {
      "x": 2,
      "y": 10,
      "z": -4,
      "name": "Plant_Leaves_Enchanted"
    },
    {
      "x": 2,
      "y": 11,
      "z": -4,
      "name": "Plant_Leaves_Enchanted"
    },
    {
      "x": 2,
      "y": 2,
      "z": -3,
      "name": "Wood_Azure_Roots"
    },
    {
      "x": 2,
      "y": 3,
      "z": -3,
      "name": "Wood_Enchanted_Trunk"
    },
    {
      "x": 2,
      "y": 4,
      "z": -3,
      "name": "Wood_Enchanted_Trunk"
    },
    {
      "x": 2,
      "y": 5,
      "z": -3,
      "name": "Wood_Enchanted_Trunk"
    },
    {
      "x": 2,
      "y": 9,
      "z": -3,
      "name": "Plant_Moss_Wall_Crystal",
      "rotation": 2
    },
    {
      "x": 2,
      "y": 10,
      "z": -3,
      "name": "Wood_Azure_Branch_Long",
      "rotation": 4
    },
    {
      "x": 2,
      "y": 13,
      "z": -3,
      "name": "Plant_Leaves_Enchanted"
    },
    {
      "x": 2,
      "y": 14,
      "z": -3,
      "name": "Plant_Leaves_Enchanted"
    },
    {
      "x": 2,
      "y": 15,
      "z": -3,
      "name": "Plant_Leaves_Enchanted"
    },
    {
      "x": 2,
      "y": 16,
      "z": -3,
      "name": "Plant_Leaves_Enchanted"
    },
    {
      "x": 2,
      "y": 4,
      "z": -2,
      "name": "Wood_Enchanted_Trunk"
    },
    {
      "x": 2,
      "y": 5,
      "z": -2,
      "name": "Wood_Enchanted_Trunk"
    },
    {
      "x": 2,
      "y": 6,
      "z": -2,
      "name": "Wood_Enchanted_Trunk"
    },
    {
      "x": 2,
      "y": 7,
      "z": -2,
      "name": "Wood_Enchanted_Trunk"
    },
    {
      "x": 2,
      "y": 8,
      "z": -2,
      "name": "Wood_Enchanted_Trunk"
    },
    {
      "x": 2,
      "y": 9,
      "z": -2,
      "name": "Wood_Enchanted_Trunk"
    },
    {
      "x": 2,
      "y": 10,
      "z": -2,
      "name": "Wood_Enchanted_Trunk"
    },
    {
      "x": 2,
      "y": 11,
      "z": -2,
      "name": "Wood_Azure_Branch_Long"
    },
    {
      "x": 2,
      "y": 12,
      "z": -2,
      "name": "Wood_Azure_Branch_Long"
    },
    {
      "x": 2,
      "y": 13,
      "z": -2,
      "name": "Plant_Leaves_Enchanted"
    },
    {
      "x": 2,
      "y": 14,
      "z": -2,
      "name": "Plant_Leaves_Enchanted"
    },
    {
      "x": 2,
      "y": 2,
      "z": -1,
      "name": "Wood_Azure_Roots"
    },
    {
      "x": 2,
      "y": 3,
      "z": -1,
      "name": "Wood_Enchanted_Trunk"
    },
    {
      "x": 2,
      "y": 4,
      "z": -1,
      "name": "Wood_Enchanted_Trunk"
    },
    {
      "x": 2,
      "y": 10,
      "z": -1,
      "name": "Wood_Azure_Branch_Long",
      "rotation": 4
    },
    {
      "x": 2,
      "y": 12,
      "z": -1,
      "name": "Plant_Leaves_Enchanted"
    },
    {
      "x": 2,
      "y": 13,
      "z": -1,
      "name": "Plant_Leaves_Enchanted"
    },
    {
      "x": 2,
      "y": 10,
      "z": 0,
      "name": "Plant_Leaves_Enchanted"
    },
    {
      "x": 2,
      "y": 11,
      "z": 0,
      "name": "Plant_Leaves_Enchanted"
    },
    {
      "x": 2,
      "y": 12,
      "z": 0,
      "name": "Plant_Leaves_Enchanted"
    },
    {
      "x": 2,
      "y": 9,
      "z": 1,
      "name": "Plant_Leaves_Enchanted"
    },
    {
      "x": 2,
      "y": 10,
      "z": 1,
      "name": "Plant_Leaves_Enchanted"
    },
    {
      "x": 2,
      "y": 11,
      "z": 1,
      "name": "Plant_Leaves_Enchanted"
    },
    {
      "x": 3,
      "y": 8,
      "z": -4,
      "name": "Plant_Leaves_Enchanted"
    },
    {
      "x": 3,
      "y": 9,
      "z": -4,
      "name": "Plant_Leaves_Enchanted"
    },
    {
      "x": 3,
      "y": 10,
      "z": -4,
      "name": "Plant_Leaves_Enchanted"
    },
    {
      "x": 3,
      "y": 12,
      "z": -3,
      "name": "Plant_Leaves_Enchanted"
    },
    {
      "x": 3,
      "y": 13,
      "z": -3,
      "name": "Plant_Leaves_Enchanted"
    },
    {
      "x": 3,
      "y": 14,
      "z": -3,
      "name": "Plant_Leaves_Enchanted"
    },
    {
      "x": 3,
      "y": 15,
      "z": -3,
      "name": "Plant_Leaves_Enchanted"
    },
    {
      "x": 3,
      "y": 1,
      "z": -2,
      "name": "Wood_Azure_Roots"
    },
    {
      "x": 3,
      "y": 2,
      "z": -2,
      "name": "Wood_Enchanted_Trunk"
    },
    {
      "x": 3,
      "y": 3,
      "z": -2,
      "name": "Wood_Enchanted_Trunk"
    },
    {
      "x": 3,
      "y": 4,
      "z": -2,
      "name": "Wood_Enchanted_Trunk"
    },
    {
      "x": 3,
      "y": 8,
      "z": -2,
      "name": "Wood_Azure_Branch_Long",
      "rotation": 5
    },
    {
      "x": 3,
      "y": 12,
      "z": -2,
      "name": "Plant_Leaves_Enchanted"
    },
    {
      "x": 3,
      "y": 13,
      "z": -2,
      "name": "Plant_Leaves_Enchanted"
    },
    {
      "x": 3,
      "y": 14,
      "z": -2,
      "name": "Plant_Leaves_Enchanted"
    },
    {
      "x": 3,
      "y": 15,
      "z": -2,
      "name": "Plant_Fruit_Enchanted"
    },
    {
      "x": 3,
      "y": 7,
      "z": -1,
      "name": "Plant_Leaves_Enchanted"
    },
    {
      "x": 3,
      "y": 8,
      "z": -1,
      "name": "Plant_Leaves_Enchanted"
    },
    {
      "x": 3,
      "y": 10,
      "z": -1,
      "name": "Plant_Leaves_Enchanted"
    },
    {
      "x": 3,
      "y": 11,
      "z": -1,
      "name": "Plant_Leaves_Enchanted"
    },
    {
      "x": 3,
      "y": 12,
      "z": -1,
      "name": "Plant_Leaves_Enchanted"
    },
    {
      "x": 3,
      "y": 13,
      "z": -1,
      "name": "Plant_Leaves_Enchanted"
    },
    {
      "x": 3,
      "y": 10,
      "z": 0,
      "name": "Plant_Leaves_Enchanted"
    },
    {
      "x": 3,
      "y": 11,
      "z": 0,
      "name": "Plant_Leaves_Enchanted"
    },
    {
      "x": 3,
      "y": 12,
      "z": 0,
      "name": "Plant_Leaves_Enchanted"
    },
    {
      "x": 4,
      "y": 8,
      "z": -4,
      "name": "Plant_Leaves_Enchanted"
    },
    {
      "x": 4,
      "y": 9,
      "z": -4,
      "name": "Plant_Leaves_Enchanted"
    },
    {
      "x": 4,
      "y": 7,
      "z": -3,
      "name": "Plant_Leaves_Enchanted"
    },
    {
      "x": 4,
      "y": 8,
      "z": -3,
      "name": "Plant_Leaves_Enchanted"
    },
    {
      "x": 4,
      "y": 9,
      "z": -3,
      "name": "Plant_Leaves_Enchanted"
    },
    {
      "x": 4,
      "y": 13,
      "z": -3,
      "name": "Plant_Leaves_Enchanted"
    },
    {
      "x": 4,
      "y": 7,
      "z": -2,
      "name": "Plant_Leaves_Enchanted"
    },
    {
      "x": 4,
      "y": 8,
      "z": -2,
      "name": "Plant_Leaves_Enchanted"
    },
    {
      "x": 4,
      "y": 11,
      "z": -2,
      "name": "Plant_Leaves_Enchanted"
    },
    {
      "x": 4,
      "y": 12,
      "z": -2,
      "name": "Plant_Leaves_Enchanted"
    },
    {
      "x": 4,
      "y": 13,
      "z": -2,
      "name": "Plant_Leaves_Enchanted"
    },
    {
      "x": 4,
      "y": 7,
      "z": -1,
      "name": "Plant_Leaves_Enchanted"
    },
    {
      "x": 4,
      "y": 11,
      "z": -1,
      "name": "Plant_Leaves_Enchanted"
    },
    {
      "x": 4,
      "y": 12,
      "z": -1,
      "name": "Plant_Leaves_Enchanted"
    },
    {
      "x": 4,
      "y": 11,
      "z": 0,
      "name": "Plant_Leaves_Enchanted"
    },
    {
      "x": 5,
      "y": 7,
      "z": -3,
      "name": "Plant_Leaves_Enchanted"
    },
    {
      "x": 5,
      "y": 8,
      "z": -3,
      "name": "Plant_Leaves_Enchanted"
    },
    {
      "x": 5,
      "y": 7,
      "z": -2,
      "name": "Plant_Leaves_Enchanted"
    }
  ]
}