{
  "version": 8,
  "blockIdVersion": 10,
  "anchorX": 0,
  "anchorY": 0,
  "anchorZ": -1,
  "blocks": [
    {
      "x": -1,
      "y": 5,
      "z": -2,
      "name": "Plant_Leaves_Enchanted"
    },
    {
      "x": -1,
      "y": 5,
      "z": -1,
      "name": "Plant_Leaves_Enchanted"
    },
    {
      "x": -1,
      "y": 6,
      "z": -1,
      "name": "Plant_Leaves_Enchanted"
    },
    {
      "x": -1,
      "y": 7,
      "z": -1,
      "name": "Plant_Leaves_Enchanted"
    },
    {
      "x": -1,
      "y": 6,
      "z": 0,
      "name": "Plant_Leaves_Enchanted"
    },
    {
      "x": -1,
      "y": 7,
      "z": 0,
      "name": "Plant_Leaves_Enchanted"
    },
    {
      "x": 0,
      "y": 4,
      "z": -2,
      "name": "Plant_Leaves_Enchanted"
    },
    {
      "x": 0,
      "y": 5,
      "z": -2,
      "name": "Plant_Leaves_Enchanted"
    },
    {
      "x": 0,
      "y": 6,
      "z": -2,
      "name": "Plant_Leaves_Enchanted"
    },
    {
      "x": 0,
      "y": 0,
      "z": -1,
      "name": "Wood_Azure_Branch_Long"
    },
    {
      "x": 0,
      "y": 1,
      "z": -1,
      "name": "Wood_Azure_Branch_Long"
    },
    {
      "x": 0,
      "y": 2,
      "z": -1,
      "name": "Wood_Azure_Branch_Long"
    },
    {
      "x": 0,
      "y": 3,
      "z": -1,
      "name": "Wood_Azure_Branch_Long"
    },
    {
      "x": 0,
      "y": 4,
      "z": -1,
      "name": "Wood_Azure_Branch_Long"
    },
    {
      "x": 0,
      "y": 5,
      "z": -1,
      "name": "Wood_Azure_Branch_Long"
    },
    {
      "x": 0,
      "y": 6,
      "z": -1,
      "name": "Plant_Leaves_Enchanted"
    },
    {
      "x": 0,
      "y": 7,
      "z": -1,
      "name": "Plant_Leaves_Enchanted"
    },
    {
      "x": 0,
      "y": 3,
      "z": 0,
      "name": "Plant_Leaves_Enchanted"
    },
    {
      "x": 0,
      "y": 6,
      "z": 0,
      "name": "Plant_Leaves_Enchanted"
    },
    {
      "x": 0,
      "y": 7,
      "z": 0,
      "name": "Plant_Leaves_Enchanted"
    },
    {
      "x": 0,
      "y": 8,
      "z": 0,
      "name": "Plant_Leaves_Enchanted"
    },
    {
      "x": 1,
      "y": 4,
      "z": -2,
      "name": "Plant_Leaves_Enchanted"
    },
    {
      "x": 1,
      "y": 5,
      "z": -2,
      "name": "Plant_Leaves_Enchanted"
    },
    {
      "x": 1,
      "y": 3,
      "z": -1,
      "name": "Plant_Leaves_Enchanted"
    },
    {
      "x": 1,
      "y": 4,
      "z": -1,
      "name": "Plant_Leaves_Enchanted"
    },
    {
      "x": 1,
      "y": 5,
      "z": -1,
      "name": "Plant_Leaves_Enchanted"
    },
    {
      "x": 1,
      "y": 3,
      "z": 0,
      "name": "Plant_Leaves_Enchanted"
    },
    {
      "x": 1,
      "y": 4,
      "z": 0,
      "name": "Plant_Leaves_Enchanted"
    },
    {
      "x": 1,
      "y": 7,
      "z": 0,
      "name": "Plant_Leaves_Enchanted"
    },
    {
      "x": 1,
      "y": 8,
      "z": 0,
      "name": "Plant_Leaves_Enchanted"
    },
    {
      "x": 1,
      "y": 9,
      "z": 0,
      "name": "Plant_Leaves_Enchanted"
    }
  ]
}